<?xml version="1.0" ?>
<!-- =================================================================================== -->
<!-- |    This document was autogenerated by xacro from scout_v2.xacro                 | -->
<!-- |    EDITING THIS FILE BY HAND IS NOT RECOMMENDED                                 | -->
<!-- =================================================================================== -->
<robot name="scout_v2">
  <!-- Base link -->
  <link name="base_link">
    <visual>
      <origin rpy="0 0 0" xyz="0 0 0"/>
      <geometry>
        <mesh filename="package://scout/scout_description/meshes/base_link.dae"/>
      </geometry>
    </visual>
    <collision>
      <origin rpy="0 0 0" xyz="0 0 0.008"/>
      <geometry>
        <box size="0.925 0.38 0.21"/>
      </geometry>
    </collision>
    <collision>
      <origin rpy="0 0 0" xyz="0 0 0.034999999999999996"/>
      <geometry>
        <box size="0.15416666666666667 0.627 0.06999999999999999"/>
      </geometry>
    </collision>
  </link>
  <!-- <joint name="chassis_link_joint" type="fixed">
        <origin xyz="0 0 ${wheel_radius - wheel_vertical_offset}" rpy="0 0 0" />
        <parent link="base_link" />
        <child link="chassis_link" />
    </joint> -->
  <link name="inertial_link">
    <inertial>
      <mass value="200"/>
      <!-- <mass value="50" /> -->
      <!-- <origin xyz="-0.00065 -0.085 0.062" />
            <inertia ixx="0.6022" ixy="-0.02364" ixz="-0.1197" iyy="1.7386" iyz="-0.001544" izz="2.0296" /> -->
      <origin xyz="0.0 0.0 0.0"/>
      <inertia ixx="2.288641" ixy="0" ixz="0" iyy="5.103976" iyz="0" izz="3.431465"/>
    </inertial>
  </link>
  <joint name="inertial_joint" type="fixed">
    <origin rpy="0 0 0" xyz="0 0 0"/>
    <parent link="base_link"/>
    <child link="inertial_link"/>
  </joint>
  <!-- For testing, hang the robot up in the air -->
  <!-- <link name="world" />
    <joint name="world_to_base_link=" type="fixed">
        <origin xyz="0 0 0.5" rpy="0 0 0" />
        <parent link="world"/>
        <child link="base_link"/>
    </joint> -->
  <link name="front_right_wheel_link">
    <inertial>
      <mass value="8"/>
      <origin xyz="0 0 0"/>
      <inertia ixx="0.1171" ixy="0" ixz="0" iyy="0.1361" iyz="0" izz="0.1171"/>
    </inertial>
    <visual>
      <origin rpy="0 0 0" xyz="0 0 0"/>
      <geometry>
        <mesh filename="package://scout/scout_description/meshes/wheel_type1.dae"/>
      </geometry>
    </visual>
    <collision>
      <origin rpy="1.570795 0 0" xyz="0 0 0"/>
      <geometry>
        <cylinder length="0.11653" radius="0.16459"/>
      </geometry>
      <contact>
        <ode>
          <min_depth>0.001</min_depth>
        </ode>
      </contact>
    </collision>
  </link>
  <joint name="front_right_wheel" type="continuous">
    <parent link="base_link"/>
    <child link="front_right_wheel_link"/>
    <origin rpy="3.14 0 0" xyz="0.249 -0.29153 -0.0702"/>
    <axis rpy="0 0 0" xyz="0 -1 0"/>
  </joint>
  <link name="front_left_wheel_link">
    <inertial>
      <mass value="8"/>
      <origin xyz="0 0 0"/>
      <inertia ixx="0.1171" ixy="0" ixz="0" iyy="0.1361" iyz="0" izz="0.1171"/>
    </inertial>
    <visual>
      <origin rpy="0 0 0" xyz="0 0 0"/>
      <geometry>
        <mesh filename="package://scout/scout_description/meshes/wheel_type1.dae"/>
      </geometry>
    </visual>
    <collision>
      <origin rpy="1.570795 0 0" xyz="0 0 0"/>
      <geometry>
        <cylinder length="0.11653" radius="0.16459"/>
      </geometry>
      <contact>
        <ode>
          <min_depth>0.001</min_depth>
        </ode>
      </contact>
    </collision>
  </link>
  <joint name="front_left_wheel" type="continuous">
    <parent link="base_link"/>
    <child link="front_left_wheel_link"/>
    <origin rpy="0 0 0" xyz="0.249 0.29153 -0.0702"/>
    <axis rpy="0 0 0" xyz="0 -1 0"/>
  </joint>
  <link name="rear_left_wheel_link">
    <inertial>
      <mass value="8"/>
      <origin xyz="0 0 0"/>
      <inertia ixx="0.1171" ixy="0" ixz="0" iyy="0.1361" iyz="0" izz="0.1171"/>
    </inertial>
    <visual>
      <origin rpy="0 0 0" xyz="0 0 0"/>
      <geometry>
        <mesh filename="package://scout/scout_description/meshes/wheel_type1.dae"/>
      </geometry>
    </visual>
    <collision>
      <origin rpy="1.570795 0 0" xyz="0 0 0"/>
      <geometry>
        <cylinder length="0.11653" radius="0.16459"/>
      </geometry>
      <contact>
        <ode>
          <min_depth>0.001</min_depth>
        </ode>
      </contact>
    </collision>
  </link>
  <joint name="rear_left_wheel" type="continuous">
    <parent link="base_link"/>
    <child link="rear_left_wheel_link"/>
    <origin rpy="0 0 0" xyz="-0.249 0.29153 -0.0702"/>
    <axis rpy="0 0 0" xyz="0 -1 0"/>
  </joint>
  <link name="rear_right_wheel_link">
    <inertial>
      <mass value="8"/>
      <origin xyz="0 0 0"/>
      <inertia ixx="0.1171" ixy="0" ixz="0" iyy="0.1361" iyz="0" izz="0.1171"/>
    </inertial>
    <visual>
      <origin rpy="0 0 0" xyz="0 0 0"/>
      <geometry>
        <mesh filename="package://scout/scout_description/meshes/wheel_type1.dae"/>
      </geometry>
    </visual>
    <collision>
      <origin rpy="1.570795 0 0" xyz="0 0 0"/>
      <geometry>
        <cylinder length="0.11653" radius="0.16459"/>
      </geometry>
      <contact>
        <ode>
          <min_depth>0.001</min_depth>
        </ode>
      </contact>
    </collision>
  </link>
  <joint name="rear_right_wheel" type="continuous">
    <parent link="base_link"/>
    <child link="rear_right_wheel_link"/>
    <origin rpy="3.14 0 0" xyz="-0.249 -0.29153 -0.0702"/>
    <axis rpy="0 0 0" xyz="0 -1 0"/>
  </joint>
  <!-- This file is a placeholder which is included by default from
       husky.urdf.xacro. If a robot is being customized and requires
       additional URDF, set the HUSKY_URDF_EXTRAS environment variable
       to the full path of the file you would like included. -->
  <!-- Additional definitions for simulation -->
  <!-- <gazebo reference="base_link">
        <material>Gazebo/Grey</material>
    </gazebo> -->
  <transmission name="front_right_wheel_trans" type="SimpleTransmission">
    <type>transmission_interface/SimpleTransmission</type>
    <actuator name="front_right_wheel_motor">
      <mechanicalReduction>1</mechanicalReduction>
    </actuator>
    <joint name="front_right_wheel">
      <hardwareInterface>hardware_interface/VelocityJointInterface</hardwareInterface>
    </joint>
  </transmission>
  <transmission name="front_left_wheel_trans" type="SimpleTransmission">
    <type>transmission_interface/SimpleTransmission</type>
    <actuator name="front_left_wheel_motor">
      <mechanicalReduction>1</mechanicalReduction>
    </actuator>
    <joint name="front_left_wheel">
      <hardwareInterface>hardware_interface/VelocityJointInterface</hardwareInterface>
    </joint>
  </transmission>
  <transmission name="rear_left_wheel_trans" type="SimpleTransmission">
    <type>transmission_interface/SimpleTransmission</type>
    <actuator name="rear_left_wheel_motor">
      <mechanicalReduction>1</mechanicalReduction>
    </actuator>
    <joint name="rear_left_wheel">
      <hardwareInterface>hardware_interface/VelocityJointInterface</hardwareInterface>
    </joint>
  </transmission>
  <transmission name="rear_right_wheel_trans" type="SimpleTransmission">
    <type>transmission_interface/SimpleTransmission</type>
    <actuator name="rear_right_wheel_motor">
      <mechanicalReduction>1</mechanicalReduction>
    </actuator>
    <joint name="rear_right_wheel">
      <hardwareInterface>hardware_interface/VelocityJointInterface</hardwareInterface>
    </joint>
  </transmission>
  <!-- Controller configurations -->
  <gazebo>
    <plugin filename="libgazebo_ros_control.so" name="gazebo_ros_control">
      <robotNamespace>/</robotNamespace>
    </plugin>
  </gazebo>
  <!-- kp spring constant, kd damping constant -->
  <gazebo reference="front_left_wheel">
    <mu1>10</mu1>
    <mu2>10</mu2>
    <kp>10000000.0</kp>
    <kd>1.0</kd>
    <minDepth>0.01</minDepth>
    <fdir1>1 0 0</fdir1>
    <maxContacts value="64"/>
  </gazebo>
  <gazebo reference="front_right_wheel">
    <mu1>10</mu1>
    <mu2>10</mu2>
    <kp>10000000.0</kp>
    <kd>1.0</kd>
    <minDepth>0.01</minDepth>
    <fdir1>1 0 0</fdir1>
    <maxContacts value="64"/>
  </gazebo>
  <gazebo reference="rear_left_wheel">
    <mu1>10</mu1>
    <mu2>10</mu2>
    <kp>10000000.0</kp>
    <kd>1.0</kd>
    <minDepth>0.01</minDepth>
    <fdir1>1 0 0</fdir1>
    <maxContacts value="64"/>
  </gazebo>
  <gazebo reference="rear_right_wheel">
    <mu1>10</mu1>
    <mu2>10</mu2>
    <kp>10000000.0</kp>
    <kd>1.0</kd>
    <minDepth>0.01</minDepth>
    <fdir1>1 0 0</fdir1>
    <maxContacts value="64"/>
  </gazebo>

  <!-- Camera link -->
  <link name="base_camera_link">
    <inertial>
      <origin rpy="0 0 0" xyz="0 0 0"/>
      <mass value="0.001"/>
      <inertia ixx="1E-5" ixy="0" ixz="0" iyy="1E-5" iyz="-0" izz="1E-5"/>
    </inertial>
  </link>
  <joint name="base_camera_joint" type="fixed">
    <origin rpy="0 0 0" xyz="0.3895 0 0.094"/>
    <parent link="base_link"/>
    <child link="base_camera_link"/>
  </joint>
  <link name="base_camera_optical_frame">
    <inertial>
      <origin rpy="0 0 0" xyz="0 0 0"/>
      <mass value="0.001"/>
      <inertia ixx="1E-5" ixy="0" ixz="0" iyy="1E-5" iyz="-0" izz="1E-5"/>
    </inertial>
  </link>
  <joint name="base_camera_optical_joint" type="fixed">
    <origin rpy="1.5707963267966 0 1.5707963267966" xyz="0 0 0"/>
    <parent link="base_camera_link"/>
    <child link="base_camera_optical_frame"/>
  </joint>
  <link name="laser_link">
    <inertial>
      <origin rpy="0 0 0" xyz="-0.0306228970175641 0.0007091682908278 0.0551974119471302"/>
      <mass value="0.00833634573995571"/>
      <inertia ixx="1.01866461240801E-06" ixy="-5.88447626567756E-08" ixz="7.83857244757914E-08" iyy="5.10039589974707E-07" iyz="-7.12664289617235E-09" izz="1.28270671527309E-06"/>
    </inertial>
    <visual>
      <origin rpy="0 0 0" xyz="0 0 0"/>
      <geometry>
        <mesh filename="package://sensors/meshes/laser_link.STL"/>
      </geometry>
      <material name="">
        <color rgba="0.792156862745098 0.819607843137255 0.933333333333333 1"/>
      </material>
    </visual>
    <collision>
      <origin rpy="0 0 0" xyz="0 0 0"/>
      <geometry>
        <mesh filename="package://sensors/meshes/laser_link_collision.STL"/>
      </geometry>
    </collision>
  </link>
  <joint name="laser_joint" type="fixed">
    <origin rpy="0 0 3.14" xyz="0.235 0 0.23"/>
    <parent link="base_link"/>
    <child link="laser_link"/>
    <axis xyz="0 0 0"/>
  </joint>
<!-- <gazebo>
      <plugin name="skid_steer_drive_controller" filename="libgazebo_ros_skid_steer_drive.so">
          <updateRate>100.0</updateRate>
          <robotNamespace></robotNamespace>
          <leftFrontJoint>front_left_wheel</leftFrontJoint>
          <rightFrontJoint>front_right_wheel</rightFrontJoint>
          <leftRearJoint>rear_left_wheel</leftRearJoint>
          <rightRearJoint>rear_right_wheel</rightRearJoint>
          <wheelSeparation>4</wheelSeparation>
          <wheelDiameter>0.32918</wheelDiameter>
          <robotBaseFrame>base_link</robotBaseFrame>
          <torque>1000</torque>
          <commandTopic>cmd_vel</commandTopic>
          <broadcastTF>true</broadcastTF>
          <odometryTopic>odom</odometryTopic>
          <odometryFrame>odom</odometryFrame>
          <covariance_x>0.000100</covariance_x>
          <covariance_y>0.000100</covariance_y>
          <covariance_yaw>0.010000</covariance_yaw>
      </plugin>
  </gazebo> -->
<!-- <gazebo>
      <plugin name="object_controller" filename="libgazebo_ros_planar_move.so">
          <commandTopic>cmd_vel</commandTopic>
          <odometryTopic>odom</odometryTopic>
          <odometryFrame>odom</odometryFrame>
          <odometryRate>20.0</odometryRate>
          <robotBaseFrame>base_footprint</robotBaseFrame>
      </plugin>
  </gazebo> -->
</robot>

